#VRML_SIM R2022a utf8
WorldInfo {
  info [
    "In this example, the robot moves down a slope."
    "The altimeter is used to record the robots height."
  ]
  title "Altimeter"
  basicTimeStep 8
  contactProperties [
    ContactProperties {
      material2 "body"
      coulombFriction [
        0
      ]
      softCFM 0.1
    }
  ]
}
Viewpoint {
  orientation -0.2697386894881805 -0.5738397758675999 0.7732715894337653 5.538267366831801
  position -1.3027938487843664 0.7322307263554658 0.9385386981410703
}
TexturedBackground {
}
TexturedBackgroundLight {
}
RectangleArena {
}
PointLight {
  attenuation 0 0 1
  intensity 0.6
  location 0.6 0 0
}
DEF SLOPE Solid {
  translation 0 0 0.15
  rotation 0 1 0 -0.4
  children [
    Shape {
      appearance OsbWood {
        textureTransform TextureTransform {
          scale 0.5 2
        }
      }
      geometry DEF BOX0 Box {
        size 0.8 0.2 0.02
      }
    }
  ]
  name "green box"
  boundingObject USE BOX0
}
Robot {
  translation 0.15967865086714308 4.715944541721397e-05 0.2284733616343721
  rotation -0.24583054769705015 8.071573249189109e-07 0.9693128193820181 -3.1415503041039226
  children [
    Altimeter {
    }
    Transform {
      translation 0 0 0.0415
      children [
        Shape {
          appearance PBRAppearance {
            baseColor 0.0820075 0.364731 0.8
            roughness 1
            metalness 0
          }
          geometry DEF BODY Cylinder {
            height 0.08
            radius 0.045
          }
        }
      ]
    }
    HingeJoint {
      jointParameters HingeJointParameters {
        position 5.136006084083559
        axis 0 1 0
        anchor 0 0 0.025
      }
      device [
        RotationalMotor {
          name "left wheel motor"
          consumptionFactor 70
        }
        PositionSensor {
          name "left wheel sensor"
        }
      ]
      endPoint Solid {
        translation 0 0.044999999999999984 0.025
        rotation -0.6990717468852197 0.699071779325391 0.1503241166868424 3.4400065859226445
        children [
          DEF WHEEL Transform {
            rotation 0.577656895078166 0.5771968951617173 -0.5771968951617173 -2.093935
            children [
              Shape {
                appearance PBRAppearance {
                  baseColor 1 0 0
                  roughness 1
                  metalness 0
                }
                geometry Cylinder {
                  height 0.01
                  radius 0.025
                }
              }
            ]
          }
        ]
        name "left wheel"
        boundingObject USE WHEEL
        physics DEF PHYSICS_WHEEL Physics {
          density -1
          mass 0.05
        }
        linearVelocity 0.04604560876150618 2.5274670606634444e-06 0.01946858696585714
        angularVelocity -9.296888751410567e-05 2.0000049976753558 -3.981714381651944e-05
      }
    }
    HingeJoint {
      jointParameters HingeJointParameters {
        position 5.136006076963579
        axis 0 1 0
        anchor 0 0 0.025
      }
      device [
        RotationalMotor {
          name "right wheel motor"
          consumptionFactor 70
        }
        PositionSensor {
          name "right wheel sensor"
        }
      ]
      endPoint Solid {
        translation 0 -0.045000000000000005 0.025
        rotation -0.6990717471588421 0.6990717795990137 0.15032411414191615 3.4400065809452673
        children [
          USE WHEEL
        ]
        boundingObject USE WHEEL
        physics USE PHYSICS_WHEEL
        linearVelocity 0.04604705838520889 2.527515435495369e-06 0.019467591053865987
        angularVelocity -9.291559527789086e-05 2.0000050235376525 -3.975897279093737e-05
      }
    }
  ]
  name "MyBot"
  contactMaterial "body"
  boundingObject Transform {
    translation 0 0 0.0415
    rotation 0 0 1 -1.570796
    children [
      USE BODY
    ]
  }
  physics Physics {
    density -1
    mass 0.5
  }
  controller "altimeter"
  linearVelocity 0.04604641045783194 2.819550286344343e-06 0.01946813062377582
  angularVelocity -1.1500391685116533e-05 5.298929031373843e-06 -1.5926486067813274e-05
}
